{"0": {"author": "abignu", "date": "1572427944760", "content": "Hi, I am having an error when calling the device:\nDeviceError                               Traceback (most recent call last)\n<ipython-input-41-5e0abc3e2a88> in <module>()\n  4 from pennylane.plugins import default_qubit\n  5 import matplotlib.pyplot as plt\n----> 6 dev = qml.device('default.qubit', wires=1)\n  7 \n  8 # Set a random seed\n\n/usr/local/lib/python3.6/dist-packages/pennylane/__init__.py in device(name, *args, **kwargs)\n128 \n129     raise DeviceError(\n--> 130         \"Device does not exist. Make sure the required plugin is installed.\"\n131     )\n132 \n\nDeviceError: Device does not exist. Make sure the required plugin is installed.\n\nHow can I solve it?\nThanks in advance1", "link": "https://discuss.pennylane.ai//t/error-when-calling-device/259/1"}, "1": {"author": "nathan", "date": "1572441108711", "content": "Hi @abignu,\n That\u2019s an unusual error. The default.qubit plugin shouldn\u2019t need any extra installation (comes pre-packaged within pennylane). My guess would be something has gone wrong with your pennylane install. Can you try the following and tell us the output?\nimport pennylane as qml\nqml.about()\n\nAlso, can you try uninstalling and reinstalling it and let me know how that works?\nThanks,\nNathan\nPS you shouldn\u2019t need to directly import the plugin (line 4 of your code). This is handled automatically by the qml.device function.1", "link": "https://discuss.pennylane.ai//t/error-when-calling-device/259/2"}, "2": {"author": "abignu", "date": "1572444923454", "content": "Hi @nathan, thanks for your reply. I was working in Google Colab. I found on another page that restarting the runtime fixes this issue. So I have already fixed it.\nThanks for your time\nAgustin1", "link": "https://discuss.pennylane.ai//t/error-when-calling-device/259/3"}, "3": {"author": "nathan", "date": "1572448815932", "content": "Glad you got it working ", "link": "https://discuss.pennylane.ai//t/error-when-calling-device/259/4"}, "4": {"author": "fmacrae", "date": "1580573669025", "content": "Hi both, I\u2019m having the same error on colab and have tried restarting the runtime a couple of times without success.\nThe output from qml.about() I get is:\nVersion: 0.7.0\nSummary: PennyLane is a Python quantum machine learning library by Xanadu Inc.\nHome-page: https://github.com/XanaduAI/pennylane\nAuthor: None\nAuthor-email: None\nLicense: Apache License 2.0\nLocation: /usr/local/lib/python3.6/dist-packages\nRequires: toml, networkx, numpy, autograd, appdirs, semantic-version, scipy\nRequired-by: PennyLane-qiskit\nPlatform info:           Linux-4.14.137+-x86_64-with-Ubuntu-18.04-bionic\nPython version:          3.6.9\nNumpy version:           1.17.5\nScipy version:           1.4.1\nInstalled devices:\n\nThis is what I\u2019m doing to install it:  https://colab.research.google.com/drive/1bPipFzEuYgNPLVeJ5HXVP-kpG1o5QFmJ 9 which I\u2019m basing on https://pennylane.ai/install.html 112 Replies", "link": "https://discuss.pennylane.ai//t/error-when-calling-device/259/5"}, "5": {"author": "fmacrae", "date": "1580573821764", "content": "Ignore me, restarted it again and it works 1", "link": "https://discuss.pennylane.ai//t/error-when-calling-device/259/6"}, "6": {"author": "Bayaniblues", "date": "1583172843968", "content": "I had the same problem with google collab, then I used this code snippet to restart runtime\nimport os\n\ndef restart_runtime():\n  os.kill(os.getpid(), 9)\nrestart_runtime()\n\nCalling qml.about() should have the following output\nName: PennyLane\nVersion: 0.8.1\nSummary: PennyLane is a Python quantum machine learning library \nby Xanadu Inc.\nHome-page: https://github.com/XanaduAI/pennylane\nAuthor: None\nAuthor-email: None\nLicense: Apache License 2.0\nLocation: /usr/local/lib/python3.6/dist-packages\nRequires: appdirs, networkx, scipy, semantic-version, numpy, toml, \nautograd\nRequired-by: \nPlatform info:           Linux-4.14.137+-x86_64-with-Ubuntu-18.04-bionic\nPython version:          3.6.9\nNumpy version:           1.17.5\nScipy version:           1.4.1\nInstalled devices:\n- default.gaussian (PennyLane-0.8.1)\n- default.qubit (PennyLane-0.8.1)\n- default.tensor (PennyLane-0.8.1)\n- default.tensor.tf (PennyLane-0.8.1)2 Replies", "link": "https://discuss.pennylane.ai//t/error-when-calling-device/259/7"}, "7": {"author": "nathan", "date": "1583175245830", "content": "If you\u2019re working manually in a colab notebook, it should also be sufficient (and probably safer?) to restart the runtime via the available menu commands (i.e., no need to script it in python)", "link": "https://discuss.pennylane.ai//t/error-when-calling-device/259/8"}, "8": {"author": "angelinaG", "date": "1592673874140", "content": "Thank you so much!\nI faced a similar issue while working in Kaggle.\nResolved after restarting the runtime environment with your code snippet.\nOnly restarting the session didn\u2019t quite help earlier.\nThank you once again", "link": "https://discuss.pennylane.ai//t/error-when-calling-device/259/9"}, "9": {"author": "angelinaG", "date": "1592673937543", "content": "Very helpful.\nI had the similar output for qml.about() earlier but resolved after restarting the environment.", "link": "https://discuss.pennylane.ai//t/error-when-calling-device/259/10"}, "10": {"author": "angelinaG", "date": "1592673968045", "content": "Thank you for posting this query", "link": "https://discuss.pennylane.ai//t/error-when-calling-device/259/11"}, "11": {"author": "Vineesha", "date": "1600880968603", "content": "Hi, I am having an issue in loading the device default.tensor.tf on Pennylane 0.11.0.\ndev = qml.device('default.tensor.tf', wires=4)\n\nThis gives the following error:\nImportError: default.tensor device requires TensorNetwork>=0.3\n\nThis is the complete error message:\nModuleNotFoundError                       Traceback (most recent call last)\nC:\\ProgramData\\Anaconda3\\envs\\tf-gpu\\lib\\site- \npackages\\pennylane\\beta\\devices\\default_tensor.py in <module>\n 26 try:\n---> 27     import tensornetwork as tn\n  28 ModuleNotFoundError: No module named 'tensornetwork'\n\nDuring handling of the above exception, another exception occurred:\n\n ImportError                               Traceback (most recent call last)\n<ipython-input-3-385680400a10> in <module>\n----> 1 dev = qml.device('default.tensor.tf', wires=4)\n\nC:\\ProgramData\\Anaconda3\\envs\\tf-gpu\\lib\\site- \npackages\\pennylane\\__init__.py in device(name, *args, **kwargs)\n182 \n183         # loads the plugin device class\n--> 184         plugin_device_class = plugin_devices[name].load()\n185 \n186         if Version(version()) not in \nSpec(plugin_device_class.pennylane_requires):\n\nC:\\ProgramData\\Anaconda3\\envs\\tf-gpu\\lib\\site- \npackages\\pkg_resources\\__init__.py in load(self, require, *args, \n**kwargs)\n2448         if require:\n2449             self.require(*args, **kwargs)\n-> 2450         return self.resolve()\n2451 \n2452     def resolve(self):\n\nC:\\ProgramData\\Anaconda3\\envs\\tf-gpu\\lib\\site-packages\\pkg_resources\\__init__.py in resolve(self)\n2454         Resolve the entry point from its module and attrs.\n2455         \"\"\"\n-> 2456         module = __import__(self.module_name, fromlist=['__name__'], level=0)\n2457         try:\n2458             return functools.reduce(getattr, self.attrs, module)\n\nC:\\ProgramData\\Anaconda3\\envs\\tf-gpu\\lib\\site-packages\\pennylane\\beta\\devices\\__init__.py in <module>\n 17 .. currentmodule:: pennylane.beta.devices\n 18 \"\"\"\n---> 19 from .default_tensor import DefaultTensor\n 20 from .default_tensor_tf import DefaultTensorTF\n\nC:\\ProgramData\\Anaconda3\\envs\\tf-gpu\\lib\\site-packages\\pennylane\\beta\\devices\\default_tensor.py in <module>\n 31         raise ImportError(\"default.tensor device requires TensorNetwork>=0.3\")\n 32 except ImportError as e:\n---> 33     raise ImportError(\"default.tensor device requires TensorNetwork>=0.3\")\n 34 \n 35 \n\nImportError: default.tensor device requires TensorNetwork>=0.3\n\nThe error persists even after upgrading my tensorflow version to 2.3.0\nimport tensorflow as tf\nprint(tf.__version__)\n2.3.0\n\nHow to resolve this?", "link": "https://discuss.pennylane.ai//t/error-when-calling-device/259/12"}, "12": {"author": "josh", "date": "1600885180197", "content": "HI @Vineesha! You will need to install TensorNetwork  2 in order to use this device. You can do this via pip:\npip install tensornetwork==0.3\n1", "link": "https://discuss.pennylane.ai//t/error-when-calling-device/259/13"}, "13": {"author": "Vineesha", "date": "1600886358193", "content": "It works! Thank you 1", "link": "https://discuss.pennylane.ai//t/error-when-calling-device/259/14"}, "14": {"author": "Amandeep", "date": "1602838478555", "content": "DeviceError: Device does not exist. Make sure the required plugin is installed.\nPlease reply solution. Error is same", "link": "https://discuss.pennylane.ai//t/error-when-calling-device/259/15"}, "15": {"author": "josh", "date": "1602842069398", "content": "Hi @Amandeep, what device are you using?\n\n\nIf you want to use a device from an external plugin, the plugin will need to be separately installed using pip before the device is available.\n\n\nIf you are using PennyLane with Google Colab, you will need to restart the runtime (Runtime \u2192 Restart Runtime) before any PennyLane devices are available.\n\n", "link": "https://discuss.pennylane.ai//t/error-when-calling-device/259/16"}, "16": {"author": "Amandeep", "date": "1602843801390", "content": "device=qiskit.aer and i am not using google colab.", "link": "https://discuss.pennylane.ai//t/error-when-calling-device/259/17"}, "17": {"author": "josh", "date": "1602865469207", "content": "\ndevice=qiskit.aer and i am not using google colab.\n\nTo access the qiskit.aer device, you will need to install the PennyLane-Qiskit plugin, if you haven\u2019t already:\npip install pennylane-qiskit\n\nIf you have installed the plugin already, then it could be something to do with your system configuration - could you post the output of qml.about()?1", "link": "https://discuss.pennylane.ai//t/error-when-calling-device/259/18"}, "18": {"author": "Amandeep", "date": "1602908975535", "content": "Name: PennyLane\nVersion: 0.11.0\nSummary: PennyLane is a Python quantum machine learning library by Xanadu Inc.\nHome-page: https://github.com/XanaduAI/pennylane\nAuthor: None\nAuthor-email: None\nLicense: Apache License 2.0\nLocation: c:\\users\\hp\\anaconda3\\lib\\site-packages\nRequires: numpy, appdirs, scipy, autograd, toml, semantic-version, networkx\nRequired-by:\nPlatform info:           Windows-10-10.0.19041-SP0\nPython version:          3.8.3\nNumpy version:           1.18.5\nScipy version:           1.5.0\nInstalled devices:\n\ndefault.gaussian (PennyLane-0.11.0)\ndefault.qubit (PennyLane-0.11.0)\ndefault.qubit.autograd (PennyLane-0.11.0)\ndefault.qubit.tf (PennyLane-0.11.0)\ndefault.tensor (PennyLane-0.11.0)\ndefault.tensor.tf (PennyLane-0.11.0)\n", "link": "https://discuss.pennylane.ai//t/error-when-calling-device/259/19"}, "19": {"author": "josh", "date": "1603030797651", "content": "@Amandeep it looks like the PennyLane-Qiskit plugin is not installed. You can install it using pip:\npip install pennylane-qiskit\n1 Reply1", "link": "https://discuss.pennylane.ai//t/error-when-calling-device/259/20"}, "20": {"author": "Amandeep", "date": "1603084918718", "content": "When I tried to install\u2026\nERROR: Command errored out with exit status 1: python setup.py egg_info Check the logs for full command output.", "link": "https://discuss.pennylane.ai//t/error-when-calling-device/259/21"}, "21": {"author": "Maria_Schuld", "date": "1603085803951", "content": "Hey @Amandeep,\nWould you mind posting the full error message, including traceback? Such an error can arise from other dependencies missing on your system, which is impossible to guess without more information.\nThanks!2 Replies", "link": "https://discuss.pennylane.ai//t/error-when-calling-device/259/22"}, "22": {"author": "Amandeep", "date": "1603087007720", "content": "ERROR: Command errored out with exit status 1:\ncommand: \u2018C:\\Users\\HP\\anaconda3\\python.exe\u2019 -c \u2018import sys, setuptools, tokenize; sys.argv[0] = \u2018\"\u2019\"\u2018C:\\Users\\HP\\AppData\\Local\\Temp\\pip-install-zgzbc20p\\pyscf\\setup.py\u2019\"\u2019\"\u2019; file=\u2019\"\u2019\"\u2018C:\\Users\\HP\\AppData\\Local\\Temp\\pip-install-zgzbc20p\\pyscf\\setup.py\u2019\"\u2019\"\u2019;f=getattr(tokenize, \u2018\"\u2019\"\u2018open\u2019\"\u2019\"\u2019, open)(file);code=f.read().replace(\u2019\"\u2019\"\u2019\\r\\n\u2019\"\u2019\"\u2019, \u2018\"\u2019\"\u2019\\n\u2019\"\u2019\"\u2019);f.close();exec(compile(code, file, \u2018\"\u2019\"\u2018exec\u2019\"\u2019\"\u2019))\u2019 egg_info --egg-base \u2018C:\\Users\\HP\\AppData\\Local\\Temp\\pip-pip-egg-info-rl8jl_nz\u2019\ncwd: C:\\Users\\HP\\AppData\\Local\\Temp\\pip-install-zgzbc20p\\pyscf\nComplete output (9 lines):\nTraceback (most recent call last):\nFile \u201c\u201d, line 1, in \nFile \u201cC:\\Users\\HP\\AppData\\Local\\Temp\\pip-install-zgzbc20p\\pyscf\\setup.py\u201d, line 206, in \nblas_path_guess = [search_lib_path(\u2018lib\u2019+x+so_ext, blas_lib_dir)\nFile \u201cC:\\Users\\HP\\AppData\\Local\\Temp\\pip-install-zgzbc20p\\pyscf\\setup.py\u201d, line 206, in \nblas_path_guess = [search_lib_path(\u2018lib\u2019+x+so_ext, blas_lib_dir)\nFile \u201cC:\\Users\\HP\\AppData\\Local\\Temp\\pip-install-zgzbc20p\\pyscf\\setup.py\u201d, line 148, in search_lib_path\npaths = os.environ.get(LD_LIBRARY_PATH, \u2018\u2019).split(os.pathsep)\nNameError: name \u2018LD_LIBRARY_PATH\u2019 is not defined\n----------------------------------------\nERROR: Command errored out with exit status 1: python setup.py egg_info Check the logs for full command output.", "link": "https://discuss.pennylane.ai//t/error-when-calling-device/259/23"}, "23": {"author": "Amandeep", "date": "1603087045891", "content": "Thank you for you prompt reply @Maria_Schuld", "link": "https://discuss.pennylane.ai//t/error-when-calling-device/259/24"}, "24": {"author": "josh", "date": "1603094927435", "content": "Hi @Amandeep, thanks for the detailed error message!\nThe issue here is that one of the dependencies of PennyLane-Qiskit, pyscf, does not support Windows.\nThe latest version of the plugin removes this dependency; you can install it directly from GitHub:\npip install git+https://github.com/PennyLaneAI/pennylane-qiskit.git\n\nAlternatively, we will be releasing the fixed version of the PennyLane Qiskit plugin tomorrow, so by tomorrow the standard pip installation should work!", "link": "https://discuss.pennylane.ai//t/error-when-calling-device/259/25"}, "25": {"author": "Amandeep", "date": "1603101171845", "content": "\n\n\n josh:\n\nGitHub - PennyLaneAI/pennylane-qiskit: The PennyLane-Qiskit plugin integrates the Qiskit quantum computing framework and IBM Q with PennyLane's quantum machine learning capabilities.\n\n\nI am not able to install directly from the given link ", "link": "https://discuss.pennylane.ai//t/error-when-calling-device/259/26"}, "26": {"author": "Maria_Schuld", "date": "1603106439805", "content": "@Amandeep, would you mind trying tomorrow (after the pennylane-qiskit plugin release of version 0.12.0) once more using the standard pip installation and reporting if this solves the issue?\nIf you would like to install from the git link, an error message may help us to understand why you\u2019re not able to do that. There is also the \u201cpro\u201d strategy of cloning the github repository and installing from there, but I suggest the usual pip install is more straight forward in your case!", "link": "https://discuss.pennylane.ai//t/error-when-calling-device/259/27"}, "27": {"author": "Amandeep", "date": "1603117120697", "content": "Okay Thanks @Maria_Schuld. I will wait and will try to do with usual pip install", "link": "https://discuss.pennylane.ai//t/error-when-calling-device/259/28"}, "28": {"author": "Amandeep", "date": "1603173399447", "content": "Whenever the standard pip installation starts working, please let me know.", "link": "https://discuss.pennylane.ai//t/error-when-calling-device/259/29"}, "29": {"author": "Amandeep", "date": "1603174198028", "content": "Could you please tell me how to get autocomplete while typing commands in PennyLane? any command specific for it", "link": "https://discuss.pennylane.ai//t/error-when-calling-device/259/30"}, "30": {"author": "Maria_Schuld", "date": "1603176049065", "content": "Dear @Amandeep,\nIf you mean the feature of getting suggestions of available functions and methods when you start typing in your editor, this is not a feature of any programming language, but the editor itself. For example, if you use PyCharm and import pennylane, the IDE in which you code should offer autocompletion:\n", "link": "https://discuss.pennylane.ai//t/error-when-calling-device/259/31"}, "31": {"author": "Amandeep", "date": "1603178035342", "content": "Yeah!! Its working now. Although, I stuck to the previous issue and waiting for pip installation to work today.", "link": "https://discuss.pennylane.ai//t/error-when-calling-device/259/32"}, "32": {"author": "Maria_Schuld", "date": "1603182444568", "content": "Hey @Amandeep,  PennyLane-Qiskit version 0.12 is released! Please try installing again with pip install pennylane-qiskit (remove the old version before installing, just to make sure) and let us know if your problem is solved!", "link": "https://discuss.pennylane.ai//t/error-when-calling-device/259/33"}, "33": {"author": "Amandeep", "date": "1603185638660", "content": "Thank you much  @Maria_Schuld.\nI uninstalled previous one and installed latest version. Now, it working fine. Thank you for solving it.1", "link": "https://discuss.pennylane.ai//t/error-when-calling-device/259/34"}, "34": {"author": "Yian_Chen", "date": "1604595455318", "content": "Hello guys, I have met same problem recently on Colab. I also met DeviceError:\n\nraise DeviceError(\u201cDevice does not exist. Make sure the required plugin is installed.\u201d)\n\nHere is my code on Colab:\n!pip install pennylane pennylane-qiskit\nimport pennylane as qml\nqml.about()\n\nAnd here is the result, I found that my \u201cInstalled devices\u201d is null !\nSuccessfully built qiskit contextvars python-constraint yfinance dlx docplex\nInstalling collected packages: semantic-version, appdirs, pennylane, sympy, immutables, contextvars, retworkx, fastjsonschema, ply, python-constraint, qiskit-terra, pybind11, qiskit-aer, cryptography, ntlm-auth, requests-ntlm, websockets, qiskit-ibmq-provider, qiskit-ignis, lxml, yfinance, dlx, inflection, quandl, docplex, qiskit-aqua, qiskit, pennylane-qiskit\n  Found existing installation: sympy 1.1.1\n    Uninstalling sympy-1.1.1:\n      Successfully uninstalled sympy-1.1.1\n  Found existing installation: lxml 4.2.6\n    Uninstalling lxml-4.2.6:\n      Successfully uninstalled lxml-4.2.6\nSuccessfully installed appdirs-1.4.4 contextvars-2.4 cryptography-3.2.1 dlx-1.0.4 docplex-2.15.194 fastjsonschema-2.14.5 immutables-0.14 inflection-0.5.1 lxml-4.6.1 ntlm-auth-1.5.0 pennylane-0.12.0 pennylane-qiskit-0.12.0 ply-3.11 pybind11-2.6.0 python-constraint-1.4.0 qiskit-0.23.0 qiskit-aer-0.7.0 qiskit-aqua-0.8.0 qiskit-ibmq-provider-0.11.0 qiskit-ignis-0.5.0 qiskit-terra-0.16.0 quandl-3.5.3 requests-ntlm-1.1.0 retworkx-0.5.0 semantic-version-2.6.0 sympy-1.6.2 websockets-8.1 yfinance-0.1.55\nName: PennyLane\nVersion: 0.12.0\nSummary: PennyLane is a Python quantum machine learning library by Xanadu Inc.\nHome-page: https://github.com/XanaduAI/pennylane\nAuthor: None\nAuthor-email: None\nLicense: Apache License 2.0\nLocation: /usr/local/lib/python3.6/dist-packages\nRequires: scipy, autograd, numpy, toml, semantic-version, networkx, appdirs\nRequired-by: PennyLane-qiskit\nPlatform info:           Linux-4.19.112+-x86_64-with-Ubuntu-18.04-bionic\nPython version:          3.6.9\nNumpy version:           1.18.5\nScipy version:           1.4.1\nInstalled devices:\n", "link": "https://discuss.pennylane.ai//t/error-when-calling-device/259/35"}, "35": {"author": "antalszava", "date": "1604615838346", "content": "Hi @Yian_Chen,\nThanks for the report!\nYes, there is an issue with finding the devices when using Colab. The reason for this is that using pip inside a Colab block does not involve restarting the Python kernel. PennyLane uses entry_points internally to register devices from plugins. These entry points are loaded when starting the Python kernel and the very first time a Colab notebook is started, PennyLane is not yet installed (hence the entry_points are not loaded).\nCurrently known workarounds include:\n\nRestarting the runtime (Runtime menu -> Restart runtime in Colab)\nImporting the devices specifically from the related plugin:\n\nCreating a device integrated with PennyLane:\nfrom pennylane.devices.default_qubit import DefaultQubit\ndev = DefaultQubit(wires=3)\n\nCreating a device from a plugin:\nfrom pennylane_qiskit import AerDevice\n\ndev = AerDevice(wires=4)\n1", "link": "https://discuss.pennylane.ai//t/error-when-calling-device/259/36"}, "36": {"author": "Yian_Chen", "date": "1604631476073", "content": "Hi @antalszava\nThanks for your reply, after import devices directly, it works !\nBest regards,\nYian_Chen", "link": "https://discuss.pennylane.ai//t/error-when-calling-device/259/37"}}